Workbook

Sheet Данные
A1: тип_респондента | B1: пол | C1: семейное_положение | D1: дети | E1: частота_покупки | F1: цена_слишком_низкая | G1: цена_выгодная_сделка | H1: цена_завышенная_но_куплю | I1: цена_слишком_высокая | J1: проживание | K1: доля_обязательных_платежей
A2: Людмила Петровна | B2: женский | C2: состоит в браке | D2: дети есть, но они уже большие (старше 18) | E2: одну пару раз в два года или реже | F2: 600 | G2: 800 | H2: 2400 | I2: 3500 | J2: город с населением до 500 тыс. человек | K2: от 50% до 75%
A3: Илья | B3: мужской | C3: в гражданском браке | D3: нет детей | E3: две-три пары в год | F3: 1500 | G3: 3800 | H3: 8700 | I3: 16500 | J3: город-миллионник | K3: менее 25%
A4: Михаил | B4: мужской | C4: состоит в браке | D4: один ребенок | E4: обычно одну пару в год | F4: 2000 | G4: 4000 | H4: 9900 | I4: 20000 | J4: город-миллионник | K4: от 25% до 50%
A5: Руслан | B5: мужской | C5: состоит в браке | D5: один ребенок | E5: две-три пары в год | F5: 800 | G5: 1800 | H5: 2700 | I5: 4500 | J5: город с населением до 500 тыс. человек | K5: от 50% до 75%
A6: Алексей | B6: мужской | C6: состоит в браке | D6: нет детей | E6: обычно одну пару в год | F6: 1800 | G6: 3800 | H6: 8400 | I6: 14500 | J6: большой город с населением несколько миллионов | K6: менее 25%
A7: Алексей | B7: мужской | C7: состоит в браке | D7: один ребенок | E7: обычно одну пару в год | F7: 1400 | G7: 4600 | H7: 7500 | I7: 13500 | J7: большой город с населением несколько миллионов | K7: менее 25%
A8: Екатерина | B8: женский | C8: состоит в браке | D8: есть двое и более | E8: обычно одну пару в год | F8: 700 | G8: 2400 | H8: 4200 | I8: 6000 | J8: город с населением до 500 тыс. человек | K8: от 50% до 75%
A9: Илья | B9: мужской | C9: в гражданском браке | D9: нет детей | E9: две-три пары в год | F9: 2000 | G9: 3600 | H9: 8400 | I9: 13000 | J9: город-миллионник | K9: менее 25%
A10: Руслан | B10: мужской | C10: состоит в браке | D10: есть двое и более | E10: две-три пары в год | F10: 800 | G10: 1800 | H10: 2700 | I10: 4000 | J10: город с населением до 500 тыс. человек | K10: от 25% до 50%
A11: Михаил | B11: мужской | C11: состоит в браке | D11: есть двое и более | E11: обычно одну пару в год | F11: 1900 | G11: 4400 | H11: 9600 | I11: 18000 | J11: город-миллионник | K11: от 25% до 50%
A12: Екатерина | B12: женский | C12: состоит в браке | D12: есть двое и более | E12: обычно одну пару в год | F12: 800 | G12: 2200 | H12: 4800 | I12: 7500 | J12: город-миллионник | K12: от 50% до 75%
A13: Алиса | B13: женский | C13: в гражданском браке | D13: нет детей | E13: обычно одну пару в год | F13: 2000 | G13: 6000 | H13: 14100 | I13: 24500 | J13: большой город с населением несколько миллионов | K13: менее 25%
... A1001: Кристина | B1001: женский | C1001: в гражданском браке | D1001: нет детей | E1001: две-три пары в год | F1001: 1300 | G1001: 3000 | H1001: 8700 | I1001: 12000 | J1001: город-миллионник | K1001: от 25% до 50%

Sheet результат
Q1: A | R1: B | S1: C | T1: D | U1: E | V1: J | W1: K
Q2: тип респондента | R2: пол | S2: семейное положение | T2: дети | U2: частота покупки | V2: проживание | W2: доля обязательных платежей
Q3: Q4:Q13 | R3: R4:R5 | S3: S4:S6 | T3: T4:T7 | U3: U4:U6 | V3: V4:V7 | W3: W4:W7
Q4: Людмила Петровна | R4: женский | S4: состоит в браке | T4: дети есть, но они уже большие (старше 18) | U4: одну пару раз в два года или реже | V4: город с населением до 500 тыс. человек | W4: от 50% до 75%
Q5: Илья | R5: мужской | S5: в гражданском браке | T5: нет детей | U5: две-три пары в год | V5: город-миллионник | W5: менее 25%
Q6: Михаил | S6: не в отношениях | T6: один ребенок | U6: обычно одну пару в год | V6: большой город с населением несколько миллионов | W6: от 25% до 50%
Q7: Руслан | T7: есть двое и более | V7: небольшой поселок / город с населением менее 100 тыс. человек
Q8: Алексей
Q9: Екатерина
Q10: Алиса
Q11: Данил
Q12: Кристина
Q13: Арина
B15: 1 Группа
B16: Тип группы | C16: Значение | D16: Выборка | F16: столб. | G16: строка | Q16: =COUNTIF(INDIRECT("Данные!"&Q$1&":"&Q$1),результат!Q4) -> 56 | R16: =COUNTIF(INDIRECT("Данные!"&R$1&":"&R$1),результат!R4) -> 364 | S16: =COUNTIF(INDIRECT("Данные!"&S$1&":"&S$1),результат!S4) -> 577 | T16: =COUNTIF(INDIRECT("Данные!"&T$1&":"&T$1),результат!T4) -> 56 | U16: =COUNTIF(INDIRECT("Данные!"&U$1&":"&U$1),результат!U4) -> 56 | V16: =COUNTIF(INDIRECT("Данные!"&V$1&":"&V$1),результат!V4) -> 230 | W16: =COUNTIF(INDIRECT("Данные!"&W$1&":"&W$1),результат!W4) -> 114
A17: Выберите свою группу и значение >> | B17: пол | C17: мужской | D17: =INDEX($Q$16:$W$25,G17,F17)&" респондентов" -> 636 респондентов | F17: =MATCH(B17,$Q$2:$W$2,0) -> 2 | G17: =MATCH(C17,INDIRECT(HLOOKUP(B17,$Q$2:$W$3,2,0)),0) -> 2 | Q17: =COUNTIF(INDIRECT("Данные!"&Q$1&":"&Q$1),результат!Q5) -> 161 | R17: =COUNTIF(INDIRECT("Данные!"&R$1&":"&R$1),результат!R5) -> 636 | S17: =COUNTIF(INDIRECT("Данные!"&S$1&":"&S$1),результат!S5) -> 184 | T17: =COUNTIF(INDIRECT("Данные!"&T$1&":"&T$1),результат!T5) -> 493 | U17: =COUNTIF(INDIRECT("Данные!"&U$1&":"&U$1),результат!U5) -> 435 | V17: =COUNTIF(INDIRECT("Данные!"&V$1&":"&V$1),результат!V5) -> 550 | W17: =COUNTIF(INDIRECT("Данные!"&W$1&":"&W$1),результат!W5) -> 495
A18: (из списка) | Q18: =COUNTIF(INDIRECT("Данные!"&Q$1&":"&Q$1),результат!Q6) -> 106 | S18: =COUNTIF(INDIRECT("Данные!"&S$1&":"&S$1),результат!S6) -> 239 | T18: =COUNTIF(INDIRECT("Данные!"&T$1&":"&T$1),результат!T6) -> 223 | U18: =COUNTIF(INDIRECT("Данные!"&U$1&":"&U$1),результат!U6) -> 509 | V18: =COUNTIF(INDIRECT("Данные!"&V$1&":"&V$1),результат!V6) -> 190 | W18: =COUNTIF(INDIRECT("Данные!"&W$1&":"&W$1),результат!W6) -> 391
B19: PMC | C19: PME | F19: График | Q19: =COUNTIF(INDIRECT("Данные!"&Q$1&":"&Q$1),результат!Q7) -> 121 | T19: =COUNTIF(INDIRECT("Данные!"&T$1&":"&T$1),результат!T7) -> 228 | V19: =COUNTIF(INDIRECT("Данные!"&V$1&":"&V$1),результат!V7) -> 30
A20: Допустимый ценовой диапазон | Q20: =COUNTIF(INDIRECT("Данные!"&Q$1&":"&Q$1),результат!Q8) -> 152
Q21: =COUNTIF(INDIRECT("Данные!"&Q$1&":"&Q$1),результат!Q9) -> 117
A22: Точка безразличия IPP | Q22: =COUNTIF(INDIRECT("Данные!"&Q$1&":"&Q$1),результат!Q10) -> 38
Q23: =COUNTIF(INDIRECT("Данные!"&Q$1&":"&Q$1),результат!Q11) -> 96
Q24: =COUNTIF(INDIRECT("Данные!"&Q$1&":"&Q$1),результат!Q12) -> 104
Q25: =COUNTIF(INDIRECT("Данные!"&Q$1&":"&Q$1),результат!Q13) -> 49
B39: 2 Группа
B40: Тип группы | C40: Значение | D40: Выборка | F40: столб. | G40: строка
A41: Выберите свою группу и значение >> | B41: пол | C41: женский | D41: =INDEX($Q$16:$W$25,G41,F41)&" респондентов" -> 364 респондентов | F41: =MATCH(B41,$Q$2:$W$2,0) -> 2 | G41: =MATCH(C41,INDIRECT(HLOOKUP(B41,$Q$2:$W$3,2,0)),0) -> 1
A42: (из списка)
B43: PMC | C43: PME | F43: График
A44: Допустимый ценовой диапазон
A46: Точка безразличия IPP
B63: 3 Группа
B64: Тип группы | C64: Значение | D64: Выборка | F64: столб. | G64: строка
A65: Выберите свою группу и значение >> | B65: проживание | C65: большой город с населением несколько миллионов | D65: =INDEX($Q$16:$W$25,G65,F65)&" респондентов" -> 190 респондентов | F65: =MATCH(B65,$Q$2:$W$2,0) -> 6 | G65: =MATCH(C65,INDIRECT(HLOOKUP(B65,$Q$2:$W$3,2,0)),0) -> 3
A66: (из списка)
B67: PMC | C67: PME | F67: График
A68: Допустимый ценовой диапазон
A70: Точка безразличия IPP
B88: 4 Группа
B89: Тип группы | C89: Значение | D89: Выборка | F89: столб. | G89: строка
...
