Workbook

Sheet ошибки
A1: ЭКСПРЕСС-КУРС | C1: Сайт клуба | D1: https://first.excel-club.ru
C2: ТГ-канал | D2: https://t.me/pivikovaexcel
A3: «ВПР в ДЕЙСТВИИ» | C3: Ютуб | D3: https://www.youtube.com/@pivikova-excel
C4: Вконтакте | D4: https://vk.com/pivikova_excel
A7: Ошибка 1: Пропуск 4-го аргумента
A9: Инв. номер | B9: Наименование ОС
B10: ❌ Неправильная формула | C10: ✅ Правильная формула
A11: INV-MSK-TR-205 | B11: =VLOOKUP($A11,справочник!$B$7:$D$27,3) -> Сейф металлический APECS LS-30 | C11: =VLOOKUP($A11,справочник!$B$7:$D$27,3,0) -> Автомобиль Volkswagen Tiguan
A12: INV-SPB-OF-002 | B12: =VLOOKUP($A12,справочник!$B$7:$D$27,3) -> Сейф металлический APECS LS-30 | C12: =VLOOKUP($A12,справочник!$B$7:$D$27,3,0) -> Принтер HP LaserJet Pro M404dn
A15: Ошибка 2: Столбец с искомым значением не первый в выбранном диапазоне
A17: Наименование ОС | B17: Дата ввода
B18: ❌ Неправильная формула | C18: ✅ Правильная формула
A19: Рабочая станция HP Z4 G4 | B19: =VLOOKUP($A19,справочник!$B$7:$J$27,6,0) -> #N/A | C19: =VLOOKUP($A19,справочник!$D$7:$G$27,4,0) -> 44885
A20: Принтер HP LaserJet Pro M404dn | B20: =VLOOKUP($A20,справочник!$B$7:$J$27,6,0) -> #N/A | C20: =VLOOKUP($A20,справочник!$D$7:$G$27,4,0) -> 44635
A22: Наименование ОС | B22: Инвентарный номер | D22: !! ССЫЛКА НА ВИДЕО про ВПР+ВЫБОР
B23: ❌ Неправильная формула | C23: ✅ Правильная формула | D23: https://youtu.be/eTihFsdDcfA?si=Oaz2CMFgJ0bEluSb
A24: Рабочая станция HP Z4 G4 | B24: =VLOOKUP($A24,справочник!$B$7:$D$27,1,0) -> #N/A | C24: =INDEX(справочник!$B$7:$D$27,20,1) -> INV-SPB-PC-234 | D24: =MATCH($A24,справочник!$D$7:$D$27,0) -> 20
A25: Принтер HP LaserJet Pro M404dn | B25: =VLOOKUP($A25,справочник!$B$7:$D$27,1,0) -> #N/A | C25: =INDEX(справочник!$B$7:$D$27,MATCH($A25,справочник!$D$7:$D$27,0),1) -> INV-MSK-OF-001 | D25: =MATCH($A25,справочник!$D$7:$D$27,0) -> 2
A28: Ошибка 3: Неправильное закрепление диапазонов
A30: Инв. номер | B30: Внутренний код
B31: ❌ Неправильная формула | C31: ✅ Правильная формула
A32: INV-SPB-IT-078 | B32: =VLOOKUP(A32,справочник!B8:C27,2,0) -> 491 | C32: =VLOOKUP($A32,справочник!$B$8:$C$27,2,0) -> 491
A33: INV-MSK-OF-001 | B33: =VLOOKUP(A33,справочник!B9:C28,2,0) -> #N/A | C33: =VLOOKUP($A33,справочник!$B$8:$C$27,2,0) -> 153
A36: Ошибка 4: Номер столбца (3ий аргумент) выходит за пределы выделяемого диапазона
A38: Инв. номер | B38: Дата ввода
B39: ❌ Неправильная формула | C39: ✅ Правильная формула
A40: INV-SPB-IT-078 | B40: =VLOOKUP($A40,справочник!$B$7:$E$27,6,0) -> #REF! | C40: =VLOOKUP($A40,справочник!$B$7:$G$27,6,0) -> 44767
A41: INV-MSK-OF-001 | B41: =VLOOKUP($A41,справочник!$B$7:$E$27,6,0) -> #REF! | C41: =VLOOKUP($A41,справочник!$B$7:$G$27,6,0) -> 44635
A44: Ошибка 5: Неверный подсчет номера столбца
A46: Инв. номер | B46: Группа ОС
B47: ❌ Неправильная формула | C47: ✅ Правильная формула
A48: INV-SPB-IT-078 | B48: =VLOOKUP(A48,справочник!$B$7:$E$27,5,0) -> #REF! | C48: =VLOOKUP(A48,справочник!$B$7:$E$27,4,0) -> IT-оборудование
A49: INV-MSK-OF-001 | B49: =VLOOKUP(A49,справочник!$B$7:$J$27,5,0) -> Москва | C49: =VLOOKUP(A49,справочник!$B$7:$E$27,4,0) -> Офисная техника
A52: Ошибка 6: Разные форматы данных (число/текст/дата)
A54: Внутренний код | B54: Наименование ОС
B55: ❌ Неправильная формула | C55: ✅ Правильная формула
A56: 153 | B56: =VLOOKUP(A56,справочник!$C$7:$D$27,2,0) -> #N/A | C56: =VLOOKUP(TEXT(A56,"@"),справочник!$C$7:$D$27,2,0) -> Принтер HP LaserJet Pro M404dn | D56: =TEXT(A56,"@") -> 153
A57: 483 | B57: =VLOOKUP(A57,справочник!$C$7:$D$27,2,0) -> #N/A | C57: =VLOOKUP(TEXT(A57,"@"),справочник!$C$7:$D$27,2,0) -> Станок ЧПУ Haas TM-1P | D57: =TEXT(A57,"@") -> 483
A59: Дата ввода | B59: Срок службы (мес)
B60: ❌ Неправильная формула | C60: ✅ Правильная формула
...

Sheet справочник
B1: ЭКСПРЕСС-КУРС | D1: Сайт клуба | E1: https://first.excel-club.ru
D2: ТГ-канал | E2: https://t.me/pivikovaexcel
B3: «ВПР в ДЕЙСТВИИ» | D3: Ютуб | E3: https://www.youtube.com/@pivikova-excel
D4: Вконтакте | E4: https://vk.com/pivikova_excel
B6: Реестр основных средств
B7: Инвентарный номер | C7: Внутренний код | D7: Наименование ОС | E7: Группа ОС | F7: Филиал | G7: Дата ввода | H7: Первонач. стоимость | I7: Срок службы (мес) | J7: Метод амортизации
B8: INV-MSK-OF-001 | C8: 153 | D8: Принтер HP LaserJet Pro M404dn | E8: Офисная техника | F8: Москва | G8: 44635 | H8: 35000 | I8: 36 | J8: Линейный
B9: INV-EKB-PD-101 | C9: 483 | D9: Станок ЧПУ Haas TM-1P | E9: Производственное | F9: Екатеринбург | G9: 44661 | H9: 1850000 | I9: 84 | J9: Уменьшаемого остатка
B10: INV-SPB-OF-002 | C10: 156 | D10: Принтер HP LaserJet Pro M404dn | E10: Офисная техника | F10: Санкт-Петербург | G10: 44671 | H10: 36500 | I10: 36 | J10: Линейный
B11: INV-MSK-TR-205 | C11: 286 | D11: Автомобиль Volkswagen Tiguan | E11: Транспорт | F11: Москва | G11: 44686 | H11: 2300000 | I11: 60 | J11: Уменьшаемого остатка
B12: INV-NSK-PD-103 | C12: 369 | D12: Станок ЧПУ Haas TM-1P | E12: Производственное | F12: Новосибирск | G12: 44696 | H12: 1870000 | I12: 84 | J12: Уменьшаемого остатка
B13: INV-KZN-TR-207 | C13: 275 | D13: Автомобиль Volkswagen Tiguan | E13: Транспорт | F13: Казань | G13: 44722 | H13: 2280000 | I13: 60 | J13: Уменьшаемого остатка
B14: INV-NSK-IT-077 | C14: 448 | D14: Сервер Dell PowerEdge R750 | E14: IT-оборудование | F14: Новосибирск | G14: 44732 | H14: 420000 | I14: 48 | J14: Линейный
B15: INV-MSK-FN-412 | C15: 354 | D15: Мебель офисная (комплект) | E15: Мебель | F15: Москва | G15: 44743 | H15: 340000 | I15: 72 | J15: Линейный
B16: INV-SPB-IT-078 | C16: 491 | D16: Сервер Dell PowerEdge R750 | E16: IT-оборудование | F16: Санкт-Петербург | G16: 44767 | H16: 435000 | I16: 48 | J16: Линейный
B17: INV-EKB-FN-413 | C17: 243 | D17: Мебель офисная (комплект) | E17: Мебель | F17: Екатеринбург | G17: 44778 | H17: 325000 | I17: 72 | J17: Линейный
B18: INV-KZN-SV-309 | C18: 387 | D18: ИБП Eaton 9PX 6000RT | E18: IT-оборудование | F18: Казань | G18: 44788 | H18: 185000 | I18: 60 | J18: Линейный
B19: INV-MSK-MD-555 | C19: 117 | D19: Медицинский аппарат УЗИ Mindray DC-8 | E19: Медоборудование | F19: Москва | G19: 44814 | H19: 3500000 | I19: 84 | J19: Уменьшаемого остатка
... B27: INV-KZN-CM-567 | C27: 189 | D27: Видеоконференц-система Poly X50 | E27: Офисная техника | F27: Казань | G27: 44900 | H27: 340000 | I27: 60 | J27: Уменьшаемого остатка
D36: 1. не указан 4ый аргумент и результат неверный 2. столбец с искомым значением не самый левый 3. неправильное закрепление и съехал диапазон при протягивании данных 4. нет совпадения (причины: опечатки, лишний пробел) 5. разные форматы данных (число-текст)
